
[Executed at: Wed Mar 14 1:50:33 PDT 2018]

None
Traceback (most recent call last):
  File "/home/ccc_v1_c79523__48809/asn24778_45/asn24782_4/asnlib/submission.py", line 8, in <module>
    from q6_work import find_path
  File "./q6_work.py", line 34, in <module>
    print(get_interchange(lines))
  File "./q6_work.py", line 19, in get_interchange
    if len(stationline(x))>=2:
TypeError: 'dict' object is not callable
Command exited with non-zero status 1
